Workbook

Sheet relatório_transacoes
A1: Pedidos dessa entrega | B1: Data Pedido | C1: Cliente | D1: Telefone | E1: Email | F1: Documento | G1: Entrega | H1: Fatur.(R$) | I1: Pgto. | J1: Parcelas | K1: Máquina de cartão | L1: CV | M1: Cidade | N1: UF | O1: Status | P1: Data Reembolso | Q1: Comissão de Total de Usuários | R1: Taxa de Transação Total | S1: Operador | T1: Comis. Op | U1: Taxa de Máq. | V1: Taxa Ent. | W1: Entregador | X1: Quilometragem | Y1: Comis. Entregador (R$) | Z1: Lucro | AA1: Histórico | AB1: OPERAÇÃO | AC1: DATA ENTREGA
A2: ordezz02x | B2: 2025-12-23 19:00:18 | C2: Antônio Augusto de Oliveira | D2: (47) 98824-2871 | F2: 816.996.386-91 | G2: 2026-01-05 18:39:30 | H2: 159.9 | I2: Pix | M2: Barra Velha | N2: SC | O2: Completo | S2: Matheus Navegantes | W2: Bruno Farias pereira | AB2: GRANDE NAVEGANTES | AC2: 05/01/2026
A3: ord5oo1yr | B3: 2025-12-23 19:43:54 | C3: Gerson Rodrigues de Oliveira | D3: (61) 99128-1339 | F3: 444.448.501-91 | G3: 2026-01-05 16:54:06 | H3: 397 | I3: Cartão de Crédito | M3: Guará | N3: DF | O3: Completo | S3: Adriel Goiânia | W3: Leonardo Cunha lima | AB3: GRANDE GOIÂNIA | AC3: 05/01/2026
A4: ordxkkq2r | B4: 2025-12-23 21:12:21 | C4: Gislene Aparecida de Morais | D4: (37) 98834-6696 | F4: 021.320.557-26 | G4: 2026-01-05 13:45:48 | H4: 150 | I4: Dinheiro | M4: Divinópolis | N4: MG | O4: Completo | S4: Tiago Belo horizonte | W4: Lucimar José martins | AB4: GRANDE BELO HORIZONTE | AC4: 05/01/2026
A5: ordjxxoly | B5: 2025-12-24 11:14:03 | C5: Angela Maria Camargos | D5: (37) 99116-3782 | F5: 811.201.171-00 | G5: 2026-01-05 09:09:32 | H5: 150 | I5: PIX | M5: Nova Serrana | N5: MG | O5: Completo | S5: Tiago Belo horizonte | W5: Lucimar José martins | AB5: GRANDE BELO HORIZONTE | AC5: 05/01/2026
A6: ordqggvql | B6: 2025-12-24 15:06:22 | C6: Emily Rose vitoriano de | D6: (11) 95890-0544 | F6: 213.550.128-05 | G6: 2026-01-05 15:52:07 | H6: 197 | I6: Dinheiro | M6: Praia Grande | N6: SP | O6: Completo | S6: Alan São paulo | W6: Mateus Brasil silva | AB6: GRANDE SÃO PAULO | AC6: 05/01/2026
A7: ord6yyzk0 | B7: 2025-12-24 17:08:43 | C7: Iris Murta | D7: (37) 98418-6575 | F7: 485.307.368-00 | G7: 2026-01-05 15:12:16 | H7: 150 | I7: Dinheiro | M7: Divinópolis | N7: MG | O7: Completo | S7: Tiago Belo horizonte | W7: Bruno Martins | AB7: GRANDE BELO HORIZONTE | AC7: 05/01/2026
A8: ordvqqzlm | B8: 2025-12-24 17:10:43 | C8: CREUZA MARIA ONEZIO | D8: (31) 99303-8539 | F8: 460.011.188-50 | G8: 2026-01-07 17:51:22 | H8: 147 | I8: Cartão de Débito | M8: Juatuba | N8: MG | O8: Completo | S8: Tiago Belo horizonte | W8: Lucimar José martins | AB8: GRANDE BELO HORIZONTE | AC8: 07/01/2026
A9: ordn99jrn | B9: 2025-12-25 07:21:44 | C9: Inês domingos da Silva Gomes | D9: (13) 98832-5682 | F9: 295.376.338-45 | G9: 2026-01-05 16:47:34 | H9: 197 | I9: Cartão de Crédito | M9: Santos | N9: SP | O9: Completo | S9: Alan São paulo | W9: Julio Cesar lima de souza | AB9: GRANDE SÃO PAULO | AC9: 05/01/2026
A10: ord2ggl56 | B10: 2025-12-25 09:54:23 | C10: Eula . 02 | D10: (27) 99225-1478 | F10: 111.824.114-28 | G10: 2026-01-05 17:54:09 | H10: 197.9 | I10: Dinheiro | M10: Serra | N10: ES | O10: Completo | S10: João Vitória | W10: Marciney' Oscar bueker de freitas | AB10: GRANDE VITÓRIA | AC10: 05/01/2026
A11: ordvqq5ym | B11: 2025-12-25 12:37:25 | C11: Sílvia Marlian Campregher | D11: (47) 99102-3520 | F11: 199.294.878-08 | G11: 2026-01-05 19:54:05 | H11: 217 | I11: PIX | M11: Jaraguá do Sul | N11: SC | O11: Completo | S11: Matheus Navegantes | W11: Bruno Augustinho matias | AB11: GRANDE NAVEGANTES | AC11: 05/01/2026
A12: ordm22qk6 | B12: 2025-12-25 13:09:24 | C12: Sílvia marlian Campregher | D12: (47) 99102-3520 | F12: 130.050.127-86 | G12: 2026-01-05 19:53:28 | H12: 150 | I12: PIX | M12: Jaraguá do Sul | N12: SC | O12: Completo | S12: Matheus Navegantes | W12: Bruno Augustinho matias | AB12: GRANDE NAVEGANTES | AC12: 05/01/2026
A13: ord7oogor | B13: 2025-12-25 14:42:33 | C13: Fátima . | D13: (37) 99945-7413 | F13: 811.843.446-04 | G13: 2026-01-05 15:07:24 | H13: 147 | I13: Dinheiro | M13: Divinópolis | N13: MG | O13: Completo | S13: Tiago Belo horizonte | W13: Bruno Martins | AB13: GRANDE BELO HORIZONTE | AC13: 05/01/2026
... A4323: ord2gnxx6 | B4323: 2026-01-07 14:59:23 | C4323: JOSEFA MOREIRA DA SILVA BARROSO | D4323: (62) 98552-9457 | F4323: 931.055.923-34 | G4323: 2026-01-07 18:35:21 | H4323: 297 | I4323: Cartão de Crédito | M4323: Goiânia | N4323: GO | O4323: Completo | S4323: Adriel Goiânia | W4323: Miguel Arcanjo nogueira junior | AB4323: GRANDE GOIÂNIA | AC4323: 07/01/2026
A4324: orddxxnmm | B4324: 2025-12-27 10:17:09 | C4324: OSNI PASSOS | D4324: (41) 99998-2343 | F4324: 768.908.482-68 | G4324: 2026-01-09 09:46:15 | H4324: 99.9 | I4324: PIX | M4324: Piraquara | N4324: PR | O4324: Completo | S4324: Gidalto Curitiba | W4324: Maicon Wiliam lemes | AB4324: GRANDE CURITIBA | AC4324: =TEXT(G4324,"dd/mm/aaaa") -> 09/01/2026
A4325: ordjxxrkv | B4325: 2025-12-27 11:30:28 | C4325: Paulo Cesar dos Santos | D4325: (13) 98876-0612 | F4325: 040.970.050-90 | G4325: 2026-01-09 17:39:43 | H4325: 149.9 | I4325: PIX | M4325: Santos | N4325: SP | O4325: Completo | S4325: Alan São paulo | W4325: Mateus Brasil silva | AB4325: GRANDE SÃO PAULO | AC4325: =TEXT(G4325,"dd/mm/aaaa") -> 09/01/2026
A4326: ord39q03o | B4326: 2025-12-28 21:10:44 | C4326: Tatiana Dobrev | D4326: (12) 98897-9018 | F4326: 185.455.338-02 | G4326: 2026-01-10 16:25:02 | H4326: 149 | I4326: PIX | M4326: São José dos Campos | N4326: SP | O4326: Completo | S4326: Alan São paulo | W4326: Joao Vitor ferraz santos | AB4326: GRANDE SÃO PAULO | AC4326: =TEXT(G4326,"dd/mm/aaaa") -> 10/01/2026
A4327: ord6y11n1 | B4327: 2025-12-29 14:42:17 | C4327: Cristiane Batista Cardeal | D4327: (12) 97401-0704 | F4327: 071.604.047-69 | G4327: 2026-01-10 14:42:41 | H4327: 150 | I4327: PIX | M4327: São José dos Campos | N4327: SP | O4327: Completo | S4327: Alan São paulo | W4327: Joao Vitor ferraz santos | AB4327: GRANDE SÃO PAULO | AC4327: =TEXT(G4327,"dd/mm/aaaa") -> 10/01/2026
A4328: ord7o6myv | B4328: 2025-12-29 16:09:00 | C4328: zenaide Lopes Teixeira | D4328: (12) 97253-3551 | F4328: 225.739.198-54 | G4328: 2026-01-10 16:10:14 | H4328: 297 | I4328: Cartão de Débito | M4328: São José dos Campos | N4328: SP | O4328: Completo | S4328: Alan São paulo | W4328: Joao Vitor ferraz santos | AB4328: GRANDE SÃO PAULO | AC4328: =TEXT(G4328,"dd/mm/aaaa") -> 10/01/2026
A4329: ordk23p1l | B4329: 2025-12-29 16:12:11 | C4329: Maione Gomes dos Santos | D4329: (37) 99985-2054 | F4329: 102.797.896-70 | G4329: 2026-01-08 08:48:02 | H4329: 197 | I4329: Cartão de Débito | M4329: Nova Serrana | N4329: MG | O4329: Completo | S4329: Tiago Belo horizonte | W4329: Lucimar José martins | AB4329: GRANDE BELO HORIZONTE | AC4329: =TEXT(G4329,"dd/mm/aaaa") -> 08/01/2026
A4330: ordvqp2j3 | B4330: 2025-12-29 16:28:40 | C4330: Maria Helena da Silva | D4330: (12) 99647-1826 | F4330: 101.414.068-44 | G4330: 2026-01-10 11:59:45 | H4330: 150 | I4330: Dinheiro | M4330: Taubaté | N4330: SP | O4330: Completo | S4330: Alan São paulo | W4330: Bruno Figueiredo pacini | AB4330: GRANDE SÃO PAULO | AC4330: =TEXT(G4330,"dd/mm/aaaa") -> 10/01/2026
A4331: ord2gz1v6/ordy7qrmv | B4331: 2025-12-29 20:02:44 | C4331: Andreia da silva | D4331: (11) 99941-2250 | F4331: 170.692.698-70 | G4331: 2026-01-09 13:08:51 | H4331: 137 | I4331: PIX | M4331: Franco da Rocha | N4331: SP | O4331: Completo | S4331: Alan São paulo | W4331: Leonardo Andrade nascimento antônio | AB4331: GRANDE SÃO PAULO | AC4331: =TEXT(G4331,"dd/mm/aaaa") -> 09/01/2026
A4332: ord2gzymz | B4332: 2025-12-30 11:16:14 | C4332: Iolanda Oliveira Ferreira da Silva | D4332: (12) 98895-0082 | F4332: 769.068.333-91 | G4332: 2026-01-10 16:30:19 | H4332: 297 | I4332: Cartão de Crédito | M4332: Jacareí | N4332: SP | O4332: Completo | S4332: Alan São paulo | W4332: Bruno Figueiredo pacini | AB4332: GRANDE SÃO PAULO | AC4332: =TEXT(G4332,"dd/mm/aaaa") -> 10/01/2026
A4333: ord9p90ev | B4333: 2025-12-30 11:34:11 | C4333: Edinalda da Conceição | D4333: (61) 99315-2600 | F4333: 027.464.591-24 | G4333: 2026-01-10 15:28:04 | H4333: 297 | I4333: Cartão de Crédito | M4333: Águas Lindas de Goiás | N4333: GO | O4333: Completo | S4333: Adriel Goiânia | W4333: Daniel Tiago das merces silva | AB4333: GRANDE GOIÂNIA | AC4333: =TEXT(G4333,"dd/mm/aaaa") -> 10/01/2026
A4334: ord5ok20r | B4334: 2025-12-30 12:33:48 | C4334: Nilma Santana | D4334: (47) 99720-0821 | F4334: 036.999.061-75 | G4334: 2026-01-10 13:52:03 | H4334: 119.9 | I4334: Cartão de Débito | M4334: Blumenau | N4334: SC | O4334: Completo | S4334: Matheus Navegantes | W4334: Bruno Farias pereira | AB4334: GRANDE NAVEGANTES | AC4334: =TEXT(G4334,"dd/mm/aaaa") -> 10/01/2026
A4335: ordgd25ev | B4335: 2025-12-30 12:35:16 | C4335: Cileia Santos Carvalho | D4335: (11) 99321-6341 | F4335: 258.054.428-33 | G4335: 2026-01-10 15:07:03 | H4335: 397 | I4335: Dinheiro | M4335: São José dos Campos | N4335: SP | O4335: Completo | S4335: Alan São paulo | W4335: Joao Vitor ferraz santos | AB4335: GRANDE SÃO PAULO | AC4335: =TEXT(G4335,"dd/mm/aaaa") -> 10/01/2026
... A8113: orddxen0k | B8113: 2026-01-10 11:20:34 | C8113: Léa De Oliveira Martins | D8113: (61) 99998-8415 | F8113: 454.590.456-49 | G8113: 2026-01-10 13:13:30 | H8113: 137 | I8113: Cartão de Débito | M8113: Aparecida de Goiânia | N8113: GO | O8113: Completo | S8113: Adriel Goiânia | W8113: Miguel Arcanjo nogueira junior | AB8113: GRANDE GOIÂNIA | AC8113: =TEXT(G8113,"dd/mm/aaaa") -> 10/01/2026
A8114: ord07pl0 | B8114: 2024-10-02 21:59:15 | C8114: Marinalva P Nunes | D8114: (92) 98158-6696 | F8114: 535.388.032-34 | G8114: 2026-01-12 11:18:07 | H8114: 150 | I8114: PIX | M8114: Manaus | N8114: AM | O8114: Completo | S8114: Giselle Manaus | W8114: Lilian Monteiro dos santos | AB8114: =_xlfn.XLOOKUP(S8114,contatos_gerentes!D:D,contatos_gerentes!B:B) -> GRANDE MANAUS | AC8114: =TEXT(G8114,"dd/mm/aaaa") -> 12/01/2026
A8115: ord2gze7z | B8115: 2025-12-30 21:48:05 | C8115: Alvaci Teresinha | D8115: (51) 99552-5895 | F8115: 441.355.408-64 | G8115: 2026-01-12 16:51:28 | H8115: 119.9 | I8115: Dinheiro | M8115: Guaíba | N8115: RS | O8115: Completo | S8115: Darlan Porto alegre | W8115: Luiz Felipe valin caetano | AB8115: =_xlfn.XLOOKUP(S8115,contatos_gerentes!D:D,contatos_gerentes!B:B) -> GRANDE PORTO ALEGRE | AC8115: =TEXT(G8115,"dd/mm/aaaa") -> 12/01/2026
A8116: ordz7d2x7 | B8116: 2025-12-31 13:46:31 | C8116: João Natanael Dornelles da Fontoura | D8116: (47) 99175-7172 | F8116: 882.347.030-72 | G8116: 2026-01-12 14:11:41 | H8116: 198.01 | I8116: Cartão de Débito | M8116: Barra Velha | N8116: SC | O8116: Completo | S8116: Matheus Navegantes | W8116: Bruno Augustinho matias | AB8116: GRANDE NAVEGANTES | AC8116: =TEXT(G8116,"dd/mm/aaaa") -> 12/01/2026
A8117: ordrjmemv | B8117: 2026-01-01 16:30:15 | C8117: Maria Rosa Nunes Alves | D8117: (51) 99679-4506 | F8117: 456.913.800-44 | G8117: 2026-01-12 16:52:51 | H8117: 129.99 | I8117: Dinheiro | M8117: Guaíba | N8117: RS | O8117: Completo | S8117: Darlan Porto alegre | W8117: Luiz Felipe valin caetano | AB8117: =_xlfn.XLOOKUP(S8117,contatos_gerentes!D:D,contatos_gerentes!B:B) -> GRANDE PORTO ALEGRE | AC8117: =TEXT(G8117,"dd/mm/aaaa") -> 12/01/2026
A8118: ordp9m13m | B8118: 2026-01-02 19:35:19 | C8118: MARCIA ELISA | D8118: (54) 99711-4696 | F8118: 022.066.018-26 | G8118: 2026-01-12 12:22:38 | H8118: 109.99 | I8118: Dinheiro | M8118: Bento Gonçalves | N8118: RS | O8118: Completo | S8118: Darlan Porto alegre | W8118: Leomar Horbach vieira | AB8118: =_xlfn.XLOOKUP(S8118,contatos_gerentes!D:D,contatos_gerentes!B:B) -> GRANDE PORTO ALEGRE | AC8118: =TEXT(G8118,"dd/mm/aaaa") -> 12/01/2026
A8119: orddx2k3o | B8119: 2026-01-02 21:18:36 | C8119: vilmar borba | D8119: (47) 99207-8915 | F8119: 017.629.589-53 | G8119: 2026-01-13 19:44:54 | H8119: 197 | I8119: Dinheiro | M8119: Joinville | N8119: SC | O8119: Completo | S8119: Matheus Navegantes | W8119: Bruno Augustinho matias | AB8119: GRANDE NAVEGANTES | AC8119: =TEXT(G8119,"dd/mm/aaaa") -> 13/01/2026
A8120: ord0lkrx0 | B8120: 2026-01-03 08:18:22 | C8120: CLAUDETE PASSAIA | D8120: (54) 99952-3720 | F8120: 674.588.740-15 | G8120: 2026-01-12 10:51:06 | H8120: 197 | I8120: Cartão de Crédito | M8120: Bento Gonçalves | N8120: RS | O8120: Completo | S8120: Darlan Porto alegre | W8120: Leomar Horbach vieira | AB8120: =_xlfn.XLOOKUP(S8120,contatos_gerentes!D:D,contatos_gerentes!B:B) -> GRANDE PORTO ALEGRE | AC8120: =TEXT(G8120,"dd/mm/aaaa") -> 12/01/2026
A8121: ord5okq05 | B8121: 2026-01-03 15:20:07 | C8121: Chirlei Helena da Silva | D8121: (37) 99802-3028 | F8121: 858.548.756-91 | G8121: 2026-01-12 11:15:03 | H8121: 197 | I8121: PIX | M8121: Divinópolis | N8121: MG | O8121: Completo | S8121: Tiago Belo horizonte | W8121: Lucimar José martins | AB8121: =_xlfn.XLOOKUP(S8121,contatos_gerentes!D:D,contatos_gerentes!B:B) -> GRANDE BELO HORIZONTE | AC8121: =TEXT(G8121,"dd/mm/aaaa") -> 12/01/2026
A8122: ord1g1lem | B8122: 2026-01-04 07:58:27 | C8122: Cristina Guimarães Santos de Jesus | D8122: (11) 99141-6082 | F8122: 288.005.058-80 | G8122: 2026-01-12 12:59:45 | H8122: 197 | I8122: Dinheiro | M8122: Jundiaí | N8122: SP | O8122: Completo | S8122: Alan São paulo | W8122: Maicon Da silva rocha | AB8122: =_xlfn.XLOOKUP(S8122,contatos_gerentes!D:D,contatos_gerentes!B:B) -> GRANDE SÃO PAULO | AC8122: =TEXT(G8122,"dd/mm/aaaa") -> 12/01/2026
A8123: ordo62mng | B8123: 2026-01-04 10:01:25 | C8123: Dioclesio Marcos | D8123: (47) 99692-3389 | F8123: 021.897.993-25 | G8123: 2026-01-13 12:32:53 | H8123: 217 | I8123: Dinheiro | M8123: Joinville | N8123: SC | O8123: Completo | S8123: Matheus Navegantes | W8123: Bruno Augustinho matias | AB8123: GRANDE NAVEGANTES | AC8123: =TEXT(G8123,"dd/mm/aaaa") -> 13/01/2026
A8124: ordp9mrye | B8124: 2026-01-04 13:26:47 | C8124: JOSE HURTADO | D8124: (95) 98413-9865 | F8124: 348.521.906-15 | G8124: 2026-01-13 14:53:22 | H8124: 100 | I8124: PIX | M8124: Joinville | N8124: SC | O8124: Completo | S8124: Matheus Navegantes | W8124: Bruno Augustinho matias | AB8124: GRANDE NAVEGANTES | AC8124: =TEXT(G8124,"dd/mm/aaaa") -> 13/01/2026
A8125: ordy7ql2j | B8125: 2026-01-04 20:38:51 | C8125: Anderson Ferreira de Lima | D8125: (12) 98892-3974 | F8125: 298.804.158-09 | G8125: 2026-01-13 12:08:03 | H8125: 169.9 | I8125: Dinheiro | M8125: Jacareí | N8125: SP | O8125: Completo | S8125: Alan São paulo | W8125: Felipe alexandre De souza | AB8125: =_xlfn.XLOOKUP(S8125,contatos_gerentes!D:D,contatos_gerentes!B:B) -> GRANDE SÃO PAULO | AC8125: =TEXT(G8125,"dd/mm/aaaa") -> 13/01/2026
A8126: ordy7qlp3 | B8126: 2026-01-05 00:01:54 | C8126: Derivaldo santos | D8126: (12) 98155-9083 | F8126: 051.491.805-56 | G8126: 2026-01-13 13:08:16 | H8126: 249.9 | I8126: Cartão de Débito | M8126: Jacareí | N8126: SP | O8126: Completo | S8126: Alan São paulo | W8126: Felipe alexandre De souza | AB8126: =_xlfn.XLOOKUP(S8126,contatos_gerentes!D:D,contatos_gerentes!B:B) -> GRANDE SÃO PAULO | AC8126: =TEXT(G8126,"dd/mm/aaaa") -> 13/01/2026
...

Sheet contatos_gerentes
A1: NOME DO GERENTE | B1: OPERAÇÃO | C1: WHATSAPP | D1: operador
A2: Gidalto Dos santos | B2: GRANDE CURITIBA | C2: 41 92005-7292 | D2: Gidalto Curitiba
A3: Juliana Fischer | B3: GRANDE RIO DE JANEIRO | C3: 21 99855-9043 | D3: Juliana Rj
A4: Aaron Lucena mendes | B4: GRANDE RECIFE | C4: 81 9575-6143 | D4: Aaron Recife
A5: Tiago Belo horizonte | B5: GRANDE BELO HORIZONTE | C5: 31 9313-4107 | D5: Tiago Belo horizonte
A6: Alan Hideki | B6: GRANDE SÃO PAULO | C6: 11 99189-9831 | D6: Alan São paulo
A7: Juliana Montezuma ellery | B7: GRANDE FORTALEZA | C7: 85 8960-0500 | D7: Juliana Fortaleza
A8: Thiago Batista | B8: GRANDE TERESINA | C8: 86 9998-0359 | D8: Thiago Teresina
A9: Darlan Rodrigues | B9: GRANDE PORTO ALEGRE | C9: 51 9800-5264 | D9: Darlan Porto alegre
A10: Franklin Torres | B10: GRANDE SÃO LUIS | C10: 98 8338-9137 | D10: Franklin São luis
A11: Angel Duarte ribeiro | B11: GRANDE NATAL | C11: 84 9827-7171 | D11: Angel Natal
A12: Roseneide Soares da silva | B12: GRANDE SALVADOR | C12: 71 8730-9506 | D12: Roseneide Salvador
... A17: Fuad Campo grande | B17: GRANDE CAMPO GRANDE | C17: 67 96542111 | D17: Fuad Campo grande
A18: Lucelia De fatima silva | B18: GRANDE JOÃO PESSOA | C18: 83 8105-4433 | D18: #N/A
A19: Matheus Navegantes | B19: GRANDE NAVEGANTES | C19: 43 9952-0929 | D19: Matheus Navegantes
A20: Michely vilhena Kikuchi | B20: GRANDE BELÉM | C20: 91 8536-3030 | D20: Michely vilhena Kikuchi

Sheet excluir_entregadores
A1: Nome do entregador
A2: Rafael Munhoz teste
A3: Rafael Teste 2
A4: Rafael Teste 3
A5: Vinícius Teste
A6: Vinicius Teste
A7: Anthony De frança santiago
A8: Edva Karlla chaves queiroz
A9: Giovanni Candido calcagnit
A10: Deivid Venceslau caze
A11: Victor Hugo da cruz alves
A12: Felipe alexandre De souza
... A25: Joao Vitor ferraz santos
